<?xml version="1.0"?>
<robot name="franka_fr3">
  <material name="fr3_white">
    <color rgba="0.96 0.96 0.96 1.0"/>
  </material>
  <material name="fr3_black">
    <color rgba="0.15 0.15 0.15 1.0"/>
  </material>
  <material name="fr3_red">
    <color rgba="0.80 0.14 0.09 1.0"/>
  </material>
  <material name="fr3_gray">
    <color rgba="0.86 0.86 0.86 1.0"/>
  </material>
  <material name="fr3_button_green">
    <color rgba="0.10 0.57 0.10 1.0"/>
  </material>
  <material name="fr3_button_red">
    <color rgba="0.52 0.01 0.01 1.0"/>
  </material>
  <material name="fr3_button_blue">
    <color rgba="0.02 0.45 0.74 1.0"/>
  </material>

  <link name="base_link">
    <visual>
      <geometry>
        <mesh filename="package://robot_mujoco/model/franka_fr3/assets/link0_0.obj"/>
      </geometry>
      <material name="fr3_black"/>
    </visual>
    <visual>
      <geometry>
        <mesh filename="package://robot_mujoco/model/franka_fr3/assets/link0_1.obj"/>
      </geometry>
      <material name="fr3_white"/>
    </visual>
    <visual>
      <geometry>
        <mesh filename="package://robot_mujoco/model/franka_fr3/assets/link0_2.obj"/>
      </geometry>
      <material name="fr3_white"/>
    </visual>
    <visual>
      <geometry>
        <mesh filename="package://robot_mujoco/model/franka_fr3/assets/link0_3.obj"/>
      </geometry>
      <material name="fr3_white"/>
    </visual>
    <visual>
      <geometry>
        <mesh filename="package://robot_mujoco/model/franka_fr3/assets/link0_4.obj"/>
      </geometry>
      <material name="fr3_white"/>
    </visual>
    <visual>
      <geometry>
        <mesh filename="package://robot_mujoco/model/franka_fr3/assets/link0_5.obj"/>
      </geometry>
      <material name="fr3_red"/>
    </visual>
    <visual>
      <geometry>
        <mesh filename="package://robot_mujoco/model/franka_fr3/assets/link0_6.obj"/>
      </geometry>
      <material name="fr3_black"/>
    </visual>
  </link>

  <link name="fr3_link1">
    <visual>
      <geometry>
        <mesh filename="package://robot_mujoco/model/franka_fr3/assets/link1.obj"/>
      </geometry>
      <material name="fr3_white"/>
    </visual>
  </link>

  <joint name="fr3_joint1" type="revolute">
    <parent link="base_link"/>
    <child link="fr3_link1"/>
    <origin xyz="0 0 0.333" rpy="0 0 0"/>
    <axis xyz="0 0 1"/>
    <limit lower="-2.7437" upper="2.7437" effort="87" velocity="3.0"/>
  </joint>

  <link name="fr3_link2">
    <visual>
      <geometry>
        <mesh filename="package://robot_mujoco/model/franka_fr3/assets/link2.obj"/>
      </geometry>
      <material name="fr3_white"/>
    </visual>
  </link>

  <joint name="fr3_joint2" type="revolute">
    <parent link="fr3_link1"/>
    <child link="fr3_link2"/>
    <origin xyz="0 0 0" rpy="-1.57079632679 0 0"/>
    <axis xyz="0 0 1"/>
    <limit lower="-1.7837" upper="1.7837" effort="87" velocity="3.0"/>
  </joint>

  <link name="fr3_link3">
    <visual>
      <geometry>
        <mesh filename="package://robot_mujoco/model/franka_fr3/assets/link3_0.obj"/>
      </geometry>
      <material name="fr3_white"/>
    </visual>
    <visual>
      <geometry>
        <mesh filename="package://robot_mujoco/model/franka_fr3/assets/link3_1.obj"/>
      </geometry>
      <material name="fr3_black"/>
    </visual>
  </link>

  <joint name="fr3_joint3" type="revolute">
    <parent link="fr3_link2"/>
    <child link="fr3_link3"/>
    <origin xyz="0 -0.316 0" rpy="1.57079632679 0 0"/>
    <axis xyz="0 0 1"/>
    <limit lower="-2.9007" upper="2.9007" effort="87" velocity="3.0"/>
  </joint>

  <link name="fr3_link4">
    <visual>
      <geometry>
        <mesh filename="package://robot_mujoco/model/franka_fr3/assets/link4_0.obj"/>
      </geometry>
      <material name="fr3_white"/>
    </visual>
    <visual>
      <geometry>
        <mesh filename="package://robot_mujoco/model/franka_fr3/assets/link4_1.obj"/>
      </geometry>
      <material name="fr3_black"/>
    </visual>
  </link>

  <joint name="fr3_joint4" type="revolute">
    <parent link="fr3_link3"/>
    <child link="fr3_link4"/>
    <origin xyz="0.0825 0 0" rpy="1.57079632679 0 0"/>
    <axis xyz="0 0 1"/>
    <limit lower="-3.0421" upper="-0.1518" effort="87" velocity="3.0"/>
  </joint>

  <link name="fr3_link5">
    <visual>
      <geometry>
        <mesh filename="package://robot_mujoco/model/franka_fr3/assets/link5_0.obj"/>
      </geometry>
      <material name="fr3_white"/>
    </visual>
    <visual>
      <geometry>
        <mesh filename="package://robot_mujoco/model/franka_fr3/assets/link5_1.obj"/>
      </geometry>
      <material name="fr3_white"/>
    </visual>
    <visual>
      <geometry>
        <mesh filename="package://robot_mujoco/model/franka_fr3/assets/link5_2.obj"/>
      </geometry>
      <material name="fr3_black"/>
    </visual>
  </link>

  <joint name="fr3_joint5" type="revolute">
    <parent link="fr3_link4"/>
    <child link="fr3_link5"/>
    <origin xyz="-0.0825 0.384 0" rpy="-1.57079632679 0 0"/>
    <axis xyz="0 0 1"/>
    <limit lower="-2.8065" upper="2.8065" effort="12" velocity="3.0"/>
  </joint>

  <link name="fr3_link6">
    <visual>
      <geometry>
        <mesh filename="package://robot_mujoco/model/franka_fr3/assets/link6_0.obj"/>
      </geometry>
      <material name="fr3_button_green"/>
    </visual>
    <visual>
      <geometry>
        <mesh filename="package://robot_mujoco/model/franka_fr3/assets/link6_1.obj"/>
      </geometry>
      <material name="fr3_white"/>
    </visual>
    <visual>
      <geometry>
        <mesh filename="package://robot_mujoco/model/franka_fr3/assets/link6_2.obj"/>
      </geometry>
      <material name="fr3_white"/>
    </visual>
    <visual>
      <geometry>
        <mesh filename="package://robot_mujoco/model/franka_fr3/assets/link6_3.obj"/>
      </geometry>
      <material name="fr3_gray"/>
    </visual>
    <visual>
      <geometry>
        <mesh filename="package://robot_mujoco/model/franka_fr3/assets/link6_4.obj"/>
      </geometry>
      <material name="fr3_button_red"/>
    </visual>
    <visual>
      <geometry>
        <mesh filename="package://robot_mujoco/model/franka_fr3/assets/link6_5.obj"/>
      </geometry>
      <material name="fr3_white"/>
    </visual>
    <visual>
      <geometry>
        <mesh filename="package://robot_mujoco/model/franka_fr3/assets/link6_6.obj"/>
      </geometry>
      <material name="fr3_black"/>
    </visual>
    <visual>
      <geometry>
        <mesh filename="package://robot_mujoco/model/franka_fr3/assets/link6_7.obj"/>
      </geometry>
      <material name="fr3_button_blue"/>
    </visual>
  </link>

  <joint name="fr3_joint6" type="revolute">
    <parent link="fr3_link5"/>
    <child link="fr3_link6"/>
    <origin xyz="0 0 0" rpy="1.57079632679 0 0"/>
    <axis xyz="0 0 1"/>
    <limit lower="0.5445" upper="4.5169" effort="12" velocity="3.0"/>
  </joint>

  <link name="fr3_link7">
    <visual>
      <geometry>
        <mesh filename="package://robot_mujoco/model/franka_fr3/assets/link7_0.obj"/>
      </geometry>
      <material name="fr3_black"/>
    </visual>
    <visual>
      <geometry>
        <mesh filename="package://robot_mujoco/model/franka_fr3/assets/link7_1.obj"/>
      </geometry>
      <material name="fr3_white"/>
    </visual>
    <visual>
      <geometry>
        <mesh filename="package://robot_mujoco/model/franka_fr3/assets/link7_2.obj"/>
      </geometry>
      <material name="fr3_white"/>
    </visual>
    <visual>
      <geometry>
        <mesh filename="package://robot_mujoco/model/franka_fr3/assets/link7_3.obj"/>
      </geometry>
      <material name="fr3_black"/>
    </visual>
  </link>

  <joint name="fr3_joint7" type="revolute">
    <parent link="fr3_link6"/>
    <child link="fr3_link7"/>
    <origin xyz="0.088 0 0" rpy="1.57079632679 0 0"/>
    <axis xyz="0 0 1"/>
    <limit lower="-3.0159" upper="3.0159" effort="12" velocity="3.0"/>
  </joint>

  <link name="fr3_tool0">
    <visual>
      <geometry>
        <sphere radius="0.03"/>
      </geometry>
      <material name="fr3_black"/>
    </visual>
  </link>

  <joint name="fr3_tool0_fixed" type="fixed">
    <parent link="fr3_link7"/>
    <child link="fr3_tool0"/>
    <origin xyz="0 0 0.107" rpy="0 0 0"/>
  </joint>

  <ros2_control name="franka_fr3_mujoco_system" type="system">
    <hardware>
      <plugin>robot_mujoco_ros2/MuJoCoHardwareInterface</plugin>
      <param name="mujoco_model_path">__MUJOCO_MODEL_PATH__</param>
      <param name="render_mode">__RENDER_MODE__</param>
      <param name="initial_keyframe">__INITIAL_KEYFRAME__</param>
      <param name="sim_speed_factor">1.0</param>
      <param name="viewer_update_rate">60.0</param>
    </hardware>

    <joint name="fr3_joint1">
      <param name="actuator_name">fr3_joint1</param>
      <command_interface name="position"/>
      <state_interface name="position"/>
      <state_interface name="velocity"/>
      <state_interface name="effort"/>
    </joint>
    <joint name="fr3_joint2">
      <param name="actuator_name">fr3_joint2</param>
      <command_interface name="position"/>
      <state_interface name="position"/>
      <state_interface name="velocity"/>
      <state_interface name="effort"/>
    </joint>
    <joint name="fr3_joint3">
      <param name="actuator_name">fr3_joint3</param>
      <command_interface name="position"/>
      <state_interface name="position"/>
      <state_interface name="velocity"/>
      <state_interface name="effort"/>
    </joint>
    <joint name="fr3_joint4">
      <param name="actuator_name">fr3_joint4</param>
      <command_interface name="position"/>
      <state_interface name="position"/>
      <state_interface name="velocity"/>
      <state_interface name="effort"/>
    </joint>
    <joint name="fr3_joint5">
      <param name="actuator_name">fr3_joint5</param>
      <command_interface name="position"/>
      <state_interface name="position"/>
      <state_interface name="velocity"/>
      <state_interface name="effort"/>
    </joint>
    <joint name="fr3_joint6">
      <param name="actuator_name">fr3_joint6</param>
      <command_interface name="position"/>
      <state_interface name="position"/>
      <state_interface name="velocity"/>
      <state_interface name="effort"/>
    </joint>
    <joint name="fr3_joint7">
      <param name="actuator_name">fr3_joint7</param>
      <command_interface name="position"/>
      <state_interface name="position"/>
      <state_interface name="velocity"/>
      <state_interface name="effort"/>
    </joint>
  </ros2_control>
</robot>
