<?xml version="1.0"?>
<robot name="franka_fr3">
  <material name="fr3_white">
    <color rgba="0.96 0.96 0.96 1.0"/>
  </material>
  <material name="fr3_black">
    <color rgba="0.15 0.15 0.15 1.0"/>
  </material>
  <material name="fr3_red">
    <color rgba="0.80 0.14 0.09 1.0"/>
  </material>

  <link name="base_link">
    <visual>
      <origin xyz="0 0 0.055" rpy="0 0 0"/>
      <geometry>
        <cylinder radius="0.09" length="0.11"/>
      </geometry>
      <material name="fr3_black"/>
    </visual>
  </link>

  <link name="fr3_link1">
    <visual>
      <origin xyz="0 0 0.16" rpy="0 0 0"/>
      <geometry>
        <cylinder radius="0.07" length="0.32"/>
      </geometry>
      <material name="fr3_white"/>
    </visual>
  </link>

  <joint name="fr3_joint1" type="revolute">
    <parent link="base_link"/>
    <child link="fr3_link1"/>
    <origin xyz="0 0 0.333" rpy="0 0 0"/>
    <axis xyz="0 0 1"/>
    <limit lower="-2.7437" upper="2.7437" effort="87" velocity="3.0"/>
  </joint>

  <link name="fr3_link2">
    <visual>
      <origin xyz="0 -0.16 0" rpy="1.57079632679 0 0"/>
      <geometry>
        <cylinder radius="0.06" length="0.32"/>
      </geometry>
      <material name="fr3_white"/>
    </visual>
  </link>

  <joint name="fr3_joint2" type="revolute">
    <parent link="fr3_link1"/>
    <child link="fr3_link2"/>
    <origin xyz="0 0 0" rpy="-1.57079632679 0 0"/>
    <axis xyz="0 0 1"/>
    <limit lower="-1.7837" upper="1.7837" effort="87" velocity="3.0"/>
  </joint>

  <link name="fr3_link3">
    <visual>
      <origin xyz="0 -0.14 0" rpy="1.57079632679 0 0"/>
      <geometry>
        <cylinder radius="0.055" length="0.28"/>
      </geometry>
      <material name="fr3_white"/>
    </visual>
  </link>

  <joint name="fr3_joint3" type="revolute">
    <parent link="fr3_link2"/>
    <child link="fr3_link3"/>
    <origin xyz="0 -0.316 0" rpy="1.57079632679 0 0"/>
    <axis xyz="0 0 1"/>
    <limit lower="-2.9007" upper="2.9007" effort="87" velocity="3.0"/>
  </joint>

  <link name="fr3_link4">
    <visual>
      <origin xyz="0.09 0 0" rpy="0 0 0"/>
      <geometry>
        <box size="0.18 0.09 0.09"/>
      </geometry>
      <material name="fr3_black"/>
    </visual>
  </link>

  <joint name="fr3_joint4" type="revolute">
    <parent link="fr3_link3"/>
    <child link="fr3_link4"/>
    <origin xyz="0.0825 0 0" rpy="1.57079632679 0 0"/>
    <axis xyz="0 0 1"/>
    <limit lower="-3.0421" upper="-0.1518" effort="87" velocity="3.0"/>
  </joint>

  <link name="fr3_link5">
    <visual>
      <origin xyz="-0.04 0.19 0" rpy="1.57079632679 0 0"/>
      <geometry>
        <cylinder radius="0.05" length="0.38"/>
      </geometry>
      <material name="fr3_white"/>
    </visual>
  </link>

  <joint name="fr3_joint5" type="revolute">
    <parent link="fr3_link4"/>
    <child link="fr3_link5"/>
    <origin xyz="-0.0825 0.384 0" rpy="-1.57079632679 0 0"/>
    <axis xyz="0 0 1"/>
    <limit lower="-2.8065" upper="2.8065" effort="12" velocity="3.0"/>
  </joint>

  <link name="fr3_link6">
    <visual>
      <origin xyz="0.06 0 0" rpy="0 0 0"/>
      <geometry>
        <box size="0.12 0.08 0.08"/>
      </geometry>
      <material name="fr3_red"/>
    </visual>
  </link>

  <joint name="fr3_joint6" type="revolute">
    <parent link="fr3_link5"/>
    <child link="fr3_link6"/>
    <origin xyz="0 0 0" rpy="1.57079632679 0 0"/>
    <axis xyz="0 0 1"/>
    <limit lower="0.5445" upper="4.5169" effort="12" velocity="3.0"/>
  </joint>

  <link name="fr3_link7">
    <visual>
      <origin xyz="0.06 0 0" rpy="0 0 0"/>
      <geometry>
        <box size="0.12 0.07 0.07"/>
      </geometry>
      <material name="fr3_white"/>
    </visual>
  </link>

  <joint name="fr3_joint7" type="revolute">
    <parent link="fr3_link6"/>
    <child link="fr3_link7"/>
    <origin xyz="0.088 0 0" rpy="1.57079632679 0 0"/>
    <axis xyz="0 0 1"/>
    <limit lower="-3.0159" upper="3.0159" effort="12" velocity="3.0"/>
  </joint>

  <link name="fr3_tool0">
    <visual>
      <geometry>
        <sphere radius="0.03"/>
      </geometry>
      <material name="fr3_black"/>
    </visual>
  </link>

  <joint name="fr3_tool0_fixed" type="fixed">
    <parent link="fr3_link7"/>
    <child link="fr3_tool0"/>
    <origin xyz="0 0 0.107" rpy="0 0 0"/>
  </joint>

  <ros2_control name="franka_fr3_mujoco_system" type="system">
    <hardware>
      <plugin>robot_mujoco_ros2/MuJoCoHardwareInterface</plugin>
      <param name="mujoco_model_path">__MUJOCO_MODEL_PATH__</param>
      <param name="render_mode">__RENDER_MODE__</param>
      <param name="initial_keyframe">__INITIAL_KEYFRAME__</param>
      <param name="sim_speed_factor">1.0</param>
      <param name="viewer_update_rate">60.0</param>
    </hardware>

    <joint name="fr3_joint1">
      <param name="actuator_name">fr3_joint1</param>
      <command_interface name="position"/>
      <state_interface name="position"/>
      <state_interface name="velocity"/>
      <state_interface name="effort"/>
    </joint>
    <joint name="fr3_joint2">
      <param name="actuator_name">fr3_joint2</param>
      <command_interface name="position"/>
      <state_interface name="position"/>
      <state_interface name="velocity"/>
      <state_interface name="effort"/>
    </joint>
    <joint name="fr3_joint3">
      <param name="actuator_name">fr3_joint3</param>
      <command_interface name="position"/>
      <state_interface name="position"/>
      <state_interface name="velocity"/>
      <state_interface name="effort"/>
    </joint>
    <joint name="fr3_joint4">
      <param name="actuator_name">fr3_joint4</param>
      <command_interface name="position"/>
      <state_interface name="position"/>
      <state_interface name="velocity"/>
      <state_interface name="effort"/>
    </joint>
    <joint name="fr3_joint5">
      <param name="actuator_name">fr3_joint5</param>
      <command_interface name="position"/>
      <state_interface name="position"/>
      <state_interface name="velocity"/>
      <state_interface name="effort"/>
    </joint>
    <joint name="fr3_joint6">
      <param name="actuator_name">fr3_joint6</param>
      <command_interface name="position"/>
      <state_interface name="position"/>
      <state_interface name="velocity"/>
      <state_interface name="effort"/>
    </joint>
    <joint name="fr3_joint7">
      <param name="actuator_name">fr3_joint7</param>
      <command_interface name="position"/>
      <state_interface name="position"/>
      <state_interface name="velocity"/>
      <state_interface name="effort"/>
    </joint>
  </ros2_control>
</robot>
